Workbook

Sheet asthma_eval
A1: Model | B1: Prompt | C1: Patient ID | D1: Expected | E1: Model Decision | F1: Correct | G1: Narrative | H1: Key
A2: gpt | B2: no_guideline | C2: 1 | D2: Asthma | E2: AlternativeDiagnosis | F2: =FALSE() -> FALSE | G2: The patient presents with a blood eosinophil count that is elevated and a FeNO level of 30.0 ppb. Spirometry is not available. FEV1 increase is 0.0% and 0.0 ml, with a predicted FEV1 increase of 0.0%. PEF variability is 0.0%. Bronchial hyperresponsiveness is not present. | H2: =A2&"|"&B2&"|"&C2 -> gpt|no_guideline|1
A3: gpt | B3: no_guideline | C3: 2 | D3: Asthma | E3: AlternativeDiagnosis | F3: =FALSE() -> FALSE | G3: The patient presents with a blood eosinophil count that is not elevated and a FeNO level of 55.0 ppb. Spirometry is not available. FEV1 increase is 0.0% and 0.0 ml, with a predicted FEV1 increase of 0.0%. PEF variability is 0.0%. Bronchial hyperresponsiveness is not present. | H3: =A3&"|"&B3&"|"&C3 -> gpt|no_guideline|2
A4: gpt | B4: no_guideline | C4: 3 | D4: Asthma | E4: Asthma | F4: =TRUE() -> TRUE | G4: The patient presents with a blood eosinophil count that is elevated and a FeNO level of 55.0 ppb. Spirometry is not available. FEV1 increase is 0.0% and 0.0 ml, with a predicted FEV1 increase of 0.0%. PEF variability is 0.0%. Bronchial hyperresponsiveness is not present. | H4: =A4&"|"&B4&"|"&C4 -> gpt|no_guideline|3
A5: gpt | B5: no_guideline | C5: 4 | D5: Asthma | E5: AlternativeDiagnosis | F5: =FALSE() -> FALSE | G5: The patient presents with a blood eosinophil count that is not elevated and a FeNO level of 50.0 ppb. Spirometry is not available. FEV1 increase is 0.0% and 0.0 ml, with a predicted FEV1 increase of 0.0%. PEF variability is 0.0%. Bronchial hyperresponsiveness is not present. | H5: =A5&"|"&B5&"|"&C5 -> gpt|no_guideline|4
A6: gpt | B6: no_guideline | C6: 11 | D6: Asthma | E6: Asthma | F6: =TRUE() -> TRUE | G6: The patient presents with a blood eosinophil count that is not elevated and a FeNO level of 30.0 ppb. Spirometry is available. FEV1 increase is 13.0% and 210.0 ml, with a predicted FEV1 increase of 5.0%. PEF variability is 0.0%. Bronchial hyperresponsiveness is not present. | H6: =A6&"|"&B6&"|"&C6 -> gpt|no_guideline|11
A7: gpt | B7: no_guideline | C7: 12 | D7: Asthma | E7: AlternativeDiagnosis | F7: =FALSE() -> FALSE | G7: The patient presents with a blood eosinophil count that is not elevated and a FeNO level of 30.0 ppb. Spirometry is available. FEV1 increase is 5.0% and 100.0 ml, with a predicted FEV1 increase of 11.0%. PEF variability is 0.0%. Bronchial hyperresponsiveness is not present. | H7: =A7&"|"&B7&"|"&C7 -> gpt|no_guideline|12
A8: gpt | B8: no_guideline | C8: 13 | D8: Asthma | E8: AlternativeDiagnosis | F8: =FALSE() -> FALSE | G8: The patient presents with a blood eosinophil count that is not elevated and a FeNO level of 30.0 ppb. Spirometry is available. FEV1 increase is 12.0% and 200.0 ml, with a predicted FEV1 increase of 5.0%. PEF variability is 0.0%. Bronchial hyperresponsiveness is not present. | H8: =A8&"|"&B8&"|"&C8 -> gpt|no_guideline|13
A9: gpt | B9: no_guideline | C9: 21 | D9: Asthma | E9: AlternativeDiagnosis | F9: =FALSE() -> FALSE | G9: The patient presents with a blood eosinophil count that is not elevated and a FeNO level of 30.0 ppb. Spirometry is not available. FEV1 increase is 0.0% and 0.0 ml, with a predicted FEV1 increase of 0.0%. PEF variability is 22.0%. Bronchial hyperresponsiveness is not present. | H9: =A9&"|"&B9&"|"&C9 -> gpt|no_guideline|21
A10: gpt | B10: no_guideline | C10: 22 | D10: Asthma | E10: AlternativeDiagnosis | F10: =FALSE() -> FALSE | G10: The patient presents with a blood eosinophil count that is not elevated and a FeNO level of 30.0 ppb. Spirometry is not available. FEV1 increase is 0.0% and 0.0 ml, with a predicted FEV1 increase of 0.0%. PEF variability is 20.0%. Bronchial hyperresponsiveness is not present. | H10: =A10&"|"&B10&"|"&C10 -> gpt|no_guideline|22
A11: gpt | B11: no_guideline | C11: 31 | D11: Asthma | E11: Asthma | F11: =TRUE() -> TRUE | G11: The patient presents with a blood eosinophil count that is not elevated and a FeNO level of 30.0 ppb. Spirometry is available. FEV1 increase is 5.0% and 100.0 ml, with a predicted FEV1 increase of 5.0%. PEF variability is 0.0%. Bronchial hyperresponsiveness is present. | H11: =A11&"|"&B11&"|"&C11 -> gpt|no_guideline|31
A12: gpt | B12: no_guideline | C12: 32 | D12: Asthma | E12: Asthma | F12: =TRUE() -> TRUE | G12: The patient presents with a blood eosinophil count that is not elevated and a FeNO level of 30.0 ppb. Spirometry is not available. FEV1 increase is 0.0% and 0.0 ml, with a predicted FEV1 increase of 0.0%. PEF variability is 10.0%. Bronchial hyperresponsiveness is present. | H12: =A12&"|"&B12&"|"&C12 -> gpt|no_guideline|32
A13: gpt | B13: no_guideline | C13: 41 | D13: AlternativeDiagnosis | E13: AlternativeDiagnosis | F13: =TRUE() -> TRUE | G13: The patient presents with a blood eosinophil count that is not elevated and a FeNO level of 30.0 ppb. Spirometry is available. FEV1 increase is 13.0% and 150.0 ml, with a predicted FEV1 increase of 5.0%. PEF variability is 0.0%. Bronchial hyperresponsiveness is not present. | H13: =A13&"|"&B13&"|"&C13 -> gpt|no_guideline|41
A14: gpt | B14: no_guideline | C14: 42 | D14: AlternativeDiagnosis | E14: AlternativeDiagnosis | F14: =TRUE() -> TRUE | G14: The patient presents with a blood eosinophil count that is not elevated and a FeNO level of 30.0 ppb. Spirometry is available. FEV1 increase is 5.0% and 210.0 ml, with a predicted FEV1 increase of 5.0%. PEF variability is 0.0%. Bronchial hyperresponsiveness is not present. | H14: =A14&"|"&B14&"|"&C14 -> gpt|no_guideline|42
A15: gpt | B15: no_guideline | C15: 51 | D15: AlternativeDiagnosis | E15: AlternativeDiagnosis | F15: =TRUE() -> TRUE | G15: The patient presents with a blood eosinophil count that is not elevated and a FeNO level of 30.0 ppb. Spirometry is available. FEV1 increase is 5.0% and 100.0 ml, with a predicted FEV1 increase of 5.0%. PEF variability is 10.0%. Bronchial hyperresponsiveness is not present. | H15: =A15&"|"&B15&"|"&C15 -> gpt|no_guideline|51
A16: gpt | B16: no_guideline | C16: 52 | D16: AlternativeDiagnosis | E16: AlternativeDiagnosis | F16: =TRUE() -> TRUE | G16: The patient presents with a blood eosinophil count that is not elevated and a FeNO level of 30.0 ppb. Spirometry is not available. FEV1 increase is 0.0% and 0.0 ml, with a predicted FEV1 increase of 0.0%. PEF variability is 10.0%. Bronchial hyperresponsiveness is not present. | H16: =A16&"|"&B16&"|"&C16 -> gpt|no_guideline|52
A17: gpt | B17: with_guideline | C17: 1 | D17: Asthma | E17: Asthma | F17: =TRUE() -> TRUE | G17: The patient presents with a blood eosinophil count that is elevated and a FeNO level of 30.0 ppb. Spirometry is not available. FEV1 increase is 0.0% and 0.0 ml, with a predicted FEV1 increase of 0.0%. PEF variability is 0.0%. Bronchial hyperresponsiveness is not present. | H17: =A17&"|"&B17&"|"&C17 -> gpt|with_guideline|1
A18: gpt | B18: with_guideline | C18: 2 | D18: Asthma | E18: Asthma | F18: =TRUE() -> TRUE | G18: The patient presents with a blood eosinophil count that is not elevated and a FeNO level of 55.0 ppb. Spirometry is not available. FEV1 increase is 0.0% and 0.0 ml, with a predicted FEV1 increase of 0.0%. PEF variability is 0.0%. Bronchial hyperresponsiveness is not present. | H18: =A18&"|"&B18&"|"&C18 -> gpt|with_guideline|2
A19: gpt | B19: with_guideline | C19: 3 | D19: Asthma | E19: Asthma | F19: =TRUE() -> TRUE | G19: The patient presents with a blood eosinophil count that is elevated and a FeNO level of 55.0 ppb. Spirometry is not available. FEV1 increase is 0.0% and 0.0 ml, with a predicted FEV1 increase of 0.0%. PEF variability is 0.0%. Bronchial hyperresponsiveness is not present. | H19: =A19&"|"&B19&"|"&C19 -> gpt|with_guideline|3
A20: gpt | B20: with_guideline | C20: 4 | D20: Asthma | E20: Asthma | F20: =TRUE() -> TRUE | G20: The patient presents with a blood eosinophil count that is not elevated and a FeNO level of 50.0 ppb. Spirometry is not available. FEV1 increase is 0.0% and 0.0 ml, with a predicted FEV1 increase of 0.0%. PEF variability is 0.0%. Bronchial hyperresponsiveness is not present. | H20: =A20&"|"&B20&"|"&C20 -> gpt|with_guideline|4
A21: gpt | B21: with_guideline | C21: 11 | D21: Asthma | E21: Asthma | F21: =TRUE() -> TRUE | G21: The patient presents with a blood eosinophil count that is not elevated and a FeNO level of 30.0 ppb. Spirometry is available. FEV1 increase is 13.0% and 210.0 ml, with a predicted FEV1 increase of 5.0%. PEF variability is 0.0%. Bronchial hyperresponsiveness is not present. | H21: =A21&"|"&B21&"|"&C21 -> gpt|with_guideline|11
A22: gpt | B22: with_guideline | C22: 12 | D22: Asthma | E22: Asthma | F22: =TRUE() -> TRUE | G22: The patient presents with a blood eosinophil count that is not elevated and a FeNO level of 30.0 ppb. Spirometry is available. FEV1 increase is 5.0% and 100.0 ml, with a predicted FEV1 increase of 11.0%. PEF variability is 0.0%. Bronchial hyperresponsiveness is not present. | H22: =A22&"|"&B22&"|"&C22 -> gpt|with_guideline|12
... A31: gpt | B31: with_guideline | C31: 52 | D31: AlternativeDiagnosis | E31: AlternativeDiagnosis | F31: =TRUE() -> TRUE | G31: The patient presents with a blood eosinophil count that is not elevated and a FeNO level of 30.0 ppb. Spirometry is not available. FEV1 increase is 0.0% and 0.0 ml, with a predicted FEV1 increase of 0.0%. PEF variability is 10.0%. Bronchial hyperresponsiveness is not present. | H31: =A31&"|"&B31&"|"&C31 -> gpt|with_guideline|52
A32: claude | B32: no_guideline | C32: 1 | D32: Asthma | E32: PARSE_ERROR | F32: =FALSE() -> FALSE | G32: The patient presents with a blood eosinophil count that is elevated and a FeNO level of 30.0 ppb. Spirometry is not available. FEV1 increase is 0.0% and 0.0 ml, with a predicted FEV1 increase of 0.0%. PEF variability is 0.0%. Bronchial hyperresponsiveness is not present. | H32: =A32&"|"&B32&"|"&C32 -> claude|no_guideline|1
A33: claude | B33: no_guideline | C33: 2 | D33: Asthma | E33: PARSE_ERROR | F33: =FALSE() -> FALSE | G33: The patient presents with a blood eosinophil count that is not elevated and a FeNO level of 55.0 ppb. Spirometry is not available. FEV1 increase is 0.0% and 0.0 ml, with a predicted FEV1 increase of 0.0%. PEF variability is 0.0%. Bronchial hyperresponsiveness is not present. | H33: =A33&"|"&B33&"|"&C33 -> claude|no_guideline|2
A34: claude | B34: no_guideline | C34: 3 | D34: Asthma | E34: PARSE_ERROR | F34: =FALSE() -> FALSE | G34: The patient presents with a blood eosinophil count that is elevated and a FeNO level of 55.0 ppb. Spirometry is not available. FEV1 increase is 0.0% and 0.0 ml, with a predicted FEV1 increase of 0.0%. PEF variability is 0.0%. Bronchial hyperresponsiveness is not present. | H34: =A34&"|"&B34&"|"&C34 -> claude|no_guideline|3
A35: claude | B35: no_guideline | C35: 4 | D35: Asthma | E35: PARSE_ERROR | F35: =FALSE() -> FALSE | G35: The patient presents with a blood eosinophil count that is not elevated and a FeNO level of 50.0 ppb. Spirometry is not available. FEV1 increase is 0.0% and 0.0 ml, with a predicted FEV1 increase of 0.0%. PEF variability is 0.0%. Bronchial hyperresponsiveness is not present. | H35: =A35&"|"&B35&"|"&C35 -> claude|no_guideline|4
A36: claude | B36: no_guideline | C36: 11 | D36: Asthma | E36: PARSE_ERROR | F36: =FALSE() -> FALSE | G36: The patient presents with a blood eosinophil count that is not elevated and a FeNO level of 30.0 ppb. Spirometry is available. FEV1 increase is 13.0% and 210.0 ml, with a predicted FEV1 increase of 5.0%. PEF variability is 0.0%. Bronchial hyperresponsiveness is not present. | H36: =A36&"|"&B36&"|"&C36 -> claude|no_guideline|11
A37: claude | B37: no_guideline | C37: 12 | D37: Asthma | E37: PARSE_ERROR | F37: =FALSE() -> FALSE | G37: The patient presents with a blood eosinophil count that is not elevated and a FeNO level of 30.0 ppb. Spirometry is available. FEV1 increase is 5.0% and 100.0 ml, with a predicted FEV1 increase of 11.0%. PEF variability is 0.0%. Bronchial hyperresponsiveness is not present. | H37: =A37&"|"&B37&"|"&C37 -> claude|no_guideline|12
A38: claude | B38: no_guideline | C38: 13 | D38: Asthma | E38: PARSE_ERROR | F38: =FALSE() -> FALSE | G38: The patient presents with a blood eosinophil count that is not elevated and a FeNO level of 30.0 ppb. Spirometry is available. FEV1 increase is 12.0% and 200.0 ml, with a predicted FEV1 increase of 5.0%. PEF variability is 0.0%. Bronchial hyperresponsiveness is not present. | H38: =A38&"|"&B38&"|"&C38 -> claude|no_guideline|13
A39: claude | B39: no_guideline | C39: 21 | D39: Asthma | E39: PARSE_ERROR | F39: =FALSE() -> FALSE | G39: The patient presents with a blood eosinophil count that is not elevated and a FeNO level of 30.0 ppb. Spirometry is not available. FEV1 increase is 0.0% and 0.0 ml, with a predicted FEV1 increase of 0.0%. PEF variability is 22.0%. Bronchial hyperresponsiveness is not present. | H39: =A39&"|"&B39&"|"&C39 -> claude|no_guideline|21
A40: claude | B40: no_guideline | C40: 22 | D40: Asthma | E40: PARSE_ERROR | F40: =FALSE() -> FALSE | G40: The patient presents with a blood eosinophil count that is not elevated and a FeNO level of 30.0 ppb. Spirometry is not available. FEV1 increase is 0.0% and 0.0 ml, with a predicted FEV1 increase of 0.0%. PEF variability is 20.0%. Bronchial hyperresponsiveness is not present. | H40: =A40&"|"&B40&"|"&C40 -> claude|no_guideline|22
A41: claude | B41: no_guideline | C41: 31 | D41: Asthma | E41: PARSE_ERROR | F41: =FALSE() -> FALSE | G41: The patient presents with a blood eosinophil count that is not elevated and a FeNO level of 30.0 ppb. Spirometry is available. FEV1 increase is 5.0% and 100.0 ml, with a predicted FEV1 increase of 5.0%. PEF variability is 0.0%. Bronchial hyperresponsiveness is present. | H41: =A41&"|"&B41&"|"&C41 -> claude|no_guideline|31
A42: claude | B42: no_guideline | C42: 32 | D42: Asthma | E42: PARSE_ERROR | F42: =FALSE() -> FALSE | G42: The patient presents with a blood eosinophil count that is not elevated and a FeNO level of 30.0 ppb. Spirometry is not available. FEV1 increase is 0.0% and 0.0 ml, with a predicted FEV1 increase of 0.0%. PEF variability is 10.0%. Bronchial hyperresponsiveness is present. | H42: =A42&"|"&B42&"|"&C42 -> claude|no_guideline|32
A43: claude | B43: no_guideline | C43: 41 | D43: AlternativeDiagnosis | E43: PARSE_ERROR | F43: =FALSE() -> FALSE | G43: The patient presents with a blood eosinophil count that is not elevated and a FeNO level of 30.0 ppb. Spirometry is available. FEV1 increase is 13.0% and 150.0 ml, with a predicted FEV1 increase of 5.0%. PEF variability is 0.0%. Bronchial hyperresponsiveness is not present. | H43: =A43&"|"&B43&"|"&C43 -> claude|no_guideline|41
... A46: claude | B46: no_guideline | C46: 52 | D46: AlternativeDiagnosis | E46: PARSE_ERROR | F46: =FALSE() -> FALSE | G46: The patient presents with a blood eosinophil count that is not elevated and a FeNO level of 30.0 ppb. Spirometry is not available. FEV1 increase is 0.0% and 0.0 ml, with a predicted FEV1 increase of 0.0%. PEF variability is 10.0%. Bronchial hyperresponsiveness is not present. | H46: =A46&"|"&B46&"|"&C46 -> claude|no_guideline|52
A47: claude | B47: with_guideline | C47: 1 | D47: Asthma | E47: Asthma | F47: =TRUE() -> TRUE | G47: The patient presents with a blood eosinophil count that is elevated and a FeNO level of 30.0 ppb. Spirometry is not available. FEV1 increase is 0.0% and 0.0 ml, with a predicted FEV1 increase of 0.0%. PEF variability is 0.0%. Bronchial hyperresponsiveness is not present. | H47: =A47&"|"&B47&"|"&C47 -> claude|with_guideline|1
A48: claude | B48: with_guideline | C48: 2 | D48: Asthma | E48: Asthma | F48: =TRUE() -> TRUE | G48: The patient presents with a blood eosinophil count that is not elevated and a FeNO level of 55.0 ppb. Spirometry is not available. FEV1 increase is 0.0% and 0.0 ml, with a predicted FEV1 increase of 0.0%. PEF variability is 0.0%. Bronchial hyperresponsiveness is not present. | H48: =A48&"|"&B48&"|"&C48 -> claude|with_guideline|2
A49: claude | B49: with_guideline | C49: 3 | D49: Asthma | E49: Asthma | F49: =TRUE() -> TRUE | G49: The patient presents with a blood eosinophil count that is elevated and a FeNO level of 55.0 ppb. Spirometry is not available. FEV1 increase is 0.0% and 0.0 ml, with a predicted FEV1 increase of 0.0%. PEF variability is 0.0%. Bronchial hyperresponsiveness is not present. | H49: =A49&"|"&B49&"|"&C49 -> claude|with_guideline|3
A50: claude | B50: with_guideline | C50: 4 | D50: Asthma | E50: PARSE_ERROR | F50: =FALSE() -> FALSE | G50: The patient presents with a blood eosinophil count that is not elevated and a FeNO level of 50.0 ppb. Spirometry is not available. FEV1 increase is 0.0% and 0.0 ml, with a predicted FEV1 increase of 0.0%. PEF variability is 0.0%. Bronchial hyperresponsiveness is not present. | H50: =A50&"|"&B50&"|"&C50 -> claude|with_guideline|4
...

Sheet hypertension_eval
A1: Model | B1: Prompt | C1: Patient ID | D1: Expected | E1: Model Decision | F1: Correct | G1: Narrative | H1: Key
A2: gpt | B2: no_guideline | C2: 1 | D2: Screen_3y | E2: Screen_3y | F2: =TRUE() -> TRUE | G2: The patient is under 40 years of age and presents with a systolic blood pressure of 110 mmHg and a diastolic blood pressure of 60 mmHg. The patient does not have high cardiovascular risk. | H2: =A2&"|"&B2&"|"&C2 -> gpt|no_guideline|1
A3: gpt | B3: no_guideline | C3: 2 | D3: Screen_1y | E3: Screen_3y | F3: =FALSE() -> FALSE | G3: The patient is aged 40 or older and presents with a systolic blood pressure of 110 mmHg and a diastolic blood pressure of 60 mmHg. The patient does not have high cardiovascular risk. | H3: =A3&"|"&B3&"|"&C3 -> gpt|no_guideline|2
A4: gpt | B4: no_guideline | C4: 11 | D4: Screen_1y | E4: Screen_3y | F4: =FALSE() -> FALSE | G4: The patient is under 40 years of age and presents with a systolic blood pressure of 120 mmHg and a diastolic blood pressure of 70 mmHg. The patient does not have high cardiovascular risk. | H4: =A4&"|"&B4&"|"&C4 -> gpt|no_guideline|11
A5: gpt | B5: no_guideline | C5: 12 | D5: Confirm | E5: Screen_1y | F5: =FALSE() -> FALSE | G5: The patient is under 40 years of age and presents with a systolic blood pressure of 120 mmHg and a diastolic blood pressure of 70 mmHg. The patient has high cardiovascular risk. | H5: =A5&"|"&B5&"|"&C5 -> gpt|no_guideline|12
A6: gpt | B6: no_guideline | C6: 13 | D6: Screen_1y | E6: Screen_3y | F6: =FALSE() -> FALSE | G6: The patient is aged 40 or older and presents with a systolic blood pressure of 120 mmHg and a diastolic blood pressure of 70 mmHg. The patient does not have high cardiovascular risk. | H6: =A6&"|"&B6&"|"&C6 -> gpt|no_guideline|13
A7: gpt | B7: no_guideline | C7: 14 | D7: Confirm | E7: Screen_1y | F7: =FALSE() -> FALSE | G7: The patient is aged 40 or older and presents with a systolic blood pressure of 120 mmHg and a diastolic blood pressure of 70 mmHg. The patient has high cardiovascular risk. | H7: =A7&"|"&B7&"|"&C7 -> gpt|no_guideline|14
A8: gpt | B8: no_guideline | C8: 26 | D8: Confirm | E8: Confirm | F8: =TRUE() -> TRUE | G8: The patient is under 40 years of age and presents with a systolic blood pressure of 140 mmHg and a diastolic blood pressure of 90 mmHg. The patient does not have high cardiovascular risk. | H8: =A8&"|"&B8&"|"&C8 -> gpt|no_guideline|26
A9: gpt | B9: no_guideline | C9: 31 | D9: Confirm | E9: Confirm | F9: =TRUE() -> TRUE | G9: The patient is under 40 years of age and presents with a systolic blood pressure of 118 mmHg and a diastolic blood pressure of 92 mmHg. The patient does not have high cardiovascular risk. | H9: =A9&"|"&B9&"|"&C9 -> gpt|no_guideline|31
A10: gpt | B10: no_guideline | C10: 33 | D10: Confirm | E10: Confirm | F10: =TRUE() -> TRUE | G10: The patient is under 40 years of age and presents with a systolic blood pressure of 152 mmHg and a diastolic blood pressure of 68 mmHg. The patient does not have high cardiovascular risk. | H10: =A10&"|"&B10&"|"&C10 -> gpt|no_guideline|33
A11: gpt | B11: no_guideline | C11: 41 | D11: ConfirmPromptly | E11: ConfirmPromptly | F11: =TRUE() -> TRUE | G11: The patient is under 40 years of age and presents with a systolic blood pressure of 160 mmHg and a diastolic blood pressure of 100 mmHg. The patient does not have high cardiovascular risk. | H11: =A11&"|"&B11&"|"&C11 -> gpt|no_guideline|41
A12: gpt | B12: no_guideline | C12: 44 | D12: ConfirmPromptly | E12: ConfirmPromptly | F12: =TRUE() -> TRUE | G12: The patient is under 40 years of age and presents with a systolic blood pressure of 165 mmHg and a diastolic blood pressure of 90 mmHg. The patient does not have high cardiovascular risk. | H12: =A12&"|"&B12&"|"&C12 -> gpt|no_guideline|44
A13: gpt | B13: no_guideline | C13: 45 | D13: ConfirmPromptly | E13: Confirm | F13: =FALSE() -> FALSE | G13: The patient is aged 40 or older and presents with a systolic blood pressure of 120 mmHg and a diastolic blood pressure of 105 mmHg. The patient does not have high cardiovascular risk. | H13: =A13&"|"&B13&"|"&C13 -> gpt|no_guideline|45
A14: gpt | B14: no_guideline | C14: 51 | D14: EvaluateEmergency | E14: ConfirmPromptly | F14: =FALSE() -> FALSE | G14: The patient is under 40 years of age and presents with a systolic blood pressure of 180 mmHg and a diastolic blood pressure of 110 mmHg. The patient does not have high cardiovascular risk. | H14: =A14&"|"&B14&"|"&C14 -> gpt|no_guideline|51
A15: gpt | B15: no_guideline | C15: 59 | D15: EvaluateEmergency | E15: ConfirmPromptly | F15: =FALSE() -> FALSE | G15: The patient is under 40 years of age and presents with a systolic blood pressure of 180 mmHg and a diastolic blood pressure of 90 mmHg. The patient does not have high cardiovascular risk. | H15: =A15&"|"&B15&"|"&C15 -> gpt|no_guideline|59
A16: gpt | B16: no_guideline | C16: 56 | D16: EvaluateEmergency | E16: Confirm | F16: =FALSE() -> FALSE | G16: The patient is aged 40 or older and presents with a systolic blood pressure of 118 mmHg and a diastolic blood pressure of 110 mmHg. The patient does not have high cardiovascular risk. | H16: =A16&"|"&B16&"|"&C16 -> gpt|no_guideline|56
A17: gpt | B17: with_guideline | C17: 1 | D17: Screen_3y | E17: Screen_3y | F17: =TRUE() -> TRUE | G17: The patient is under 40 years of age and presents with a systolic blood pressure of 110 mmHg and a diastolic blood pressure of 60 mmHg. The patient does not have high cardiovascular risk. | H17: =A17&"|"&B17&"|"&C17 -> gpt|with_guideline|1
A18: gpt | B18: with_guideline | C18: 2 | D18: Screen_1y | E18: Screen_1y | F18: =TRUE() -> TRUE | G18: The patient is aged 40 or older and presents with a systolic blood pressure of 110 mmHg and a diastolic blood pressure of 60 mmHg. The patient does not have high cardiovascular risk. | H18: =A18&"|"&B18&"|"&C18 -> gpt|with_guideline|2
A19: gpt | B19: with_guideline | C19: 11 | D19: Screen_1y | E19: Screen_1y | F19: =TRUE() -> TRUE | G19: The patient is under 40 years of age and presents with a systolic blood pressure of 120 mmHg and a diastolic blood pressure of 70 mmHg. The patient does not have high cardiovascular risk. | H19: =A19&"|"&B19&"|"&C19 -> gpt|with_guideline|11
A20: gpt | B20: with_guideline | C20: 12 | D20: Confirm | E20: Confirm | F20: =TRUE() -> TRUE | G20: The patient is under 40 years of age and presents with a systolic blood pressure of 120 mmHg and a diastolic blood pressure of 70 mmHg. The patient has high cardiovascular risk. | H20: =A20&"|"&B20&"|"&C20 -> gpt|with_guideline|12
A21: gpt | B21: with_guideline | C21: 13 | D21: Screen_1y | E21: Screen_1y | F21: =TRUE() -> TRUE | G21: The patient is aged 40 or older and presents with a systolic blood pressure of 120 mmHg and a diastolic blood pressure of 70 mmHg. The patient does not have high cardiovascular risk. | H21: =A21&"|"&B21&"|"&C21 -> gpt|with_guideline|13
A22: gpt | B22: with_guideline | C22: 14 | D22: Confirm | E22: Confirm | F22: =TRUE() -> TRUE | G22: The patient is aged 40 or older and presents with a systolic blood pressure of 120 mmHg and a diastolic blood pressure of 70 mmHg. The patient has high cardiovascular risk. | H22: =A22&"|"&B22&"|"&C22 -> gpt|with_guideline|14
A23: gpt | B23: with_guideline | C23: 26 | D23: Confirm | E23: Confirm | F23: =TRUE() -> TRUE | G23: The patient is under 40 years of age and presents with a systolic blood pressure of 140 mmHg and a diastolic blood pressure of 90 mmHg. The patient does not have high cardiovascular risk. | H23: =A23&"|"&B23&"|"&C23 -> gpt|with_guideline|26
A24: gpt | B24: with_guideline | C24: 31 | D24: Confirm | E24: Confirm | F24: =TRUE() -> TRUE | G24: The patient is under 40 years of age and presents with a systolic blood pressure of 118 mmHg and a diastolic blood pressure of 92 mmHg. The patient does not have high cardiovascular risk. | H24: =A24&"|"&B24&"|"&C24 -> gpt|with_guideline|31
A25: gpt | B25: with_guideline | C25: 33 | D25: Confirm | E25: Confirm | F25: =TRUE() -> TRUE | G25: The patient is under 40 years of age and presents with a systolic blood pressure of 152 mmHg and a diastolic blood pressure of 68 mmHg. The patient does not have high cardiovascular risk. | H25: =A25&"|"&B25&"|"&C25 -> gpt|with_guideline|33
A26: gpt | B26: with_guideline | C26: 41 | D26: ConfirmPromptly | E26: ConfirmPromptly | F26: =TRUE() -> TRUE | G26: The patient is under 40 years of age and presents with a systolic blood pressure of 160 mmHg and a diastolic blood pressure of 100 mmHg. The patient does not have high cardiovascular risk. | H26: =A26&"|"&B26&"|"&C26 -> gpt|with_guideline|41
A27: gpt | B27: with_guideline | C27: 44 | D27: ConfirmPromptly | E27: ConfirmPromptly | F27: =TRUE() -> TRUE | G27: The patient is under 40 years of age and presents with a systolic blood pressure of 165 mmHg and a diastolic blood pressure of 90 mmHg. The patient does not have high cardiovascular risk. | H27: =A27&"|"&B27&"|"&C27 -> gpt|with_guideline|44
A28: gpt | B28: with_guideline | C28: 45 | D28: ConfirmPromptly | E28: ConfirmPromptly | F28: =TRUE() -> TRUE | G28: The patient is aged 40 or older and presents with a systolic blood pressure of 120 mmHg and a diastolic blood pressure of 105 mmHg. The patient does not have high cardiovascular risk. | H28: =A28&"|"&B28&"|"&C28 -> gpt|with_guideline|45
... A32: claude | B32: no_guideline | C32: 1 | D32: Screen_3y | E32: Screen_3y | F32: =TRUE() -> TRUE | G32: The patient is under 40 years of age and presents with a systolic blood pressure of 110 mmHg and a diastolic blood pressure of 60 mmHg. The patient does not have high cardiovascular risk. | H32: =A32&"|"&B32&"|"&C32 -> claude|no_guideline|1
A33: claude | B33: no_guideline | C33: 2 | D33: Screen_1y | E33: Screen_3y | F33: =FALSE() -> FALSE | G33: The patient is aged 40 or older and presents with a systolic blood pressure of 110 mmHg and a diastolic blood pressure of 60 mmHg. The patient does not have high cardiovascular risk. | H33: =A33&"|"&B33&"|"&C33 -> claude|no_guideline|2
A34: claude | B34: no_guideline | C34: 11 | D34: Screen_1y | E34: Screen_3y | F34: =FALSE() -> FALSE | G34: The patient is under 40 years of age and presents with a systolic blood pressure of 120 mmHg and a diastolic blood pressure of 70 mmHg. The patient does not have high cardiovascular risk. | H34: =A34&"|"&B34&"|"&C34 -> claude|no_guideline|11
A35: claude | B35: no_guideline | C35: 12 | D35: Confirm | E35: PARSE_ERROR | F35: =FALSE() -> FALSE | G35: The patient is under 40 years of age and presents with a systolic blood pressure of 120 mmHg and a diastolic blood pressure of 70 mmHg. The patient has high cardiovascular risk. | H35: =A35&"|"&B35&"|"&C35 -> claude|no_guideline|12
A36: claude | B36: no_guideline | C36: 13 | D36: Screen_1y | E36: PARSE_ERROR | F36: =FALSE() -> FALSE | G36: The patient is aged 40 or older and presents with a systolic blood pressure of 120 mmHg and a diastolic blood pressure of 70 mmHg. The patient does not have high cardiovascular risk. | H36: =A36&"|"&B36&"|"&C36 -> claude|no_guideline|13
A37: claude | B37: no_guideline | C37: 14 | D37: Confirm | E37: PARSE_ERROR | F37: =FALSE() -> FALSE | G37: The patient is aged 40 or older and presents with a systolic blood pressure of 120 mmHg and a diastolic blood pressure of 70 mmHg. The patient has high cardiovascular risk. | H37: =A37&"|"&B37&"|"&C37 -> claude|no_guideline|14
A38: claude | B38: no_guideline | C38: 26 | D38: Confirm | E38: PARSE_ERROR | F38: =FALSE() -> FALSE | G38: The patient is under 40 years of age and presents with a systolic blood pressure of 140 mmHg and a diastolic blood pressure of 90 mmHg. The patient does not have high cardiovascular risk. | H38: =A38&"|"&B38&"|"&C38 -> claude|no_guideline|26
A39: claude | B39: no_guideline | C39: 31 | D39: Confirm | E39: PARSE_ERROR | F39: =FALSE() -> FALSE | G39: The patient is under 40 years of age and presents with a systolic blood pressure of 118 mmHg and a diastolic blood pressure of 92 mmHg. The patient does not have high cardiovascular risk. | H39: =A39&"|"&B39&"|"&C39 -> claude|no_guideline|31
A40: claude | B40: no_guideline | C40: 33 | D40: Confirm | E40: PARSE_ERROR | F40: =FALSE() -> FALSE | G40: The patient is under 40 years of age and presents with a systolic blood pressure of 152 mmHg and a diastolic blood pressure of 68 mmHg. The patient does not have high cardiovascular risk. | H40: =A40&"|"&B40&"|"&C40 -> claude|no_guideline|33
A41: claude | B41: no_guideline | C41: 41 | D41: ConfirmPromptly | E41: ConfirmPromptly | F41: =TRUE() -> TRUE | G41: The patient is under 40 years of age and presents with a systolic blood pressure of 160 mmHg and a diastolic blood pressure of 100 mmHg. The patient does not have high cardiovascular risk. | H41: =A41&"|"&B41&"|"&C41 -> claude|no_guideline|41
A42: claude | B42: no_guideline | C42: 44 | D42: ConfirmPromptly | E42: PARSE_ERROR | F42: =FALSE() -> FALSE | G42: The patient is under 40 years of age and presents with a systolic blood pressure of 165 mmHg and a diastolic blood pressure of 90 mmHg. The patient does not have high cardiovascular risk. | H42: =A42&"|"&B42&"|"&C42 -> claude|no_guideline|44
A43: claude | B43: no_guideline | C43: 45 | D43: ConfirmPromptly | E43: PARSE_ERROR | F43: =FALSE() -> FALSE | G43: The patient is aged 40 or older and presents with a systolic blood pressure of 120 mmHg and a diastolic blood pressure of 105 mmHg. The patient does not have high cardiovascular risk. | H43: =A43&"|"&B43&"|"&C43 -> claude|no_guideline|45
...

Sheet curb_eval
A1: Model | B1: Prompt | C1: Patient ID | D1: Expected | E1: Model Decision | F1: Correct | G1: Narrative | H1: Key
A2: gpt | B2: no_guideline | C2: 1 | D2: Group1 | E2: Group1 | F2: =TRUE() -> TRUE | G2: The patient has an Abbreviated Mental Test Score (AMTS) of 10 out of 10. Blood urea is 5.0 mmol/L. Respiratory rate is 16 breaths per minute. Blood pressure is 120/80 mmHg. The patient is younger than 65 years of age. | H2: =A2&"|"&B2&"|"&C2 -> gpt|no_guideline|1
A3: gpt | B3: no_guideline | C3: 11 | D3: Group1 | E3: Group1 | F3: =TRUE() -> TRUE | G3: The patient has an Abbreviated Mental Test Score (AMTS) of 9 out of 10. Blood urea is 5.0 mmol/L. Respiratory rate is 16 breaths per minute. Blood pressure is 120/80 mmHg. The patient is 65 years of age or older. | H3: =A3&"|"&B3&"|"&C3 -> gpt|no_guideline|11
A4: gpt | B4: no_guideline | C4: 12 | D4: Group2 | E4: Group2 | F4: =TRUE() -> TRUE | G4: The patient has an Abbreviated Mental Test Score (AMTS) of 8 out of 10. Blood urea is 5.0 mmol/L. Respiratory rate is 16 breaths per minute. Blood pressure is 120/80 mmHg. The patient is 65 years of age or older. | H4: =A4&"|"&B4&"|"&C4 -> gpt|no_guideline|12
A5: gpt | B5: no_guideline | C5: 13 | D5: Group1 | E5: Group1 | F5: =TRUE() -> TRUE | G5: The patient has an Abbreviated Mental Test Score (AMTS) of 10 out of 10. Blood urea is 7.0 mmol/L. Respiratory rate is 16 breaths per minute. Blood pressure is 120/80 mmHg. The patient is 65 years of age or older. | H5: =A5&"|"&B5&"|"&C5 -> gpt|no_guideline|13
A6: gpt | B6: no_guideline | C6: 14 | D6: Group2 | E6: Group2 | F6: =TRUE() -> TRUE | G6: The patient has an Abbreviated Mental Test Score (AMTS) of 10 out of 10. Blood urea is 7.1 mmol/L. Respiratory rate is 16 breaths per minute. Blood pressure is 120/80 mmHg. The patient is 65 years of age or older. | H6: =A6&"|"&B6&"|"&C6 -> gpt|no_guideline|14
A7: gpt | B7: no_guideline | C7: 15 | D7: Group1 | E7: Group2 | F7: =FALSE() -> FALSE | G7: The patient has an Abbreviated Mental Test Score (AMTS) of 10 out of 10. Blood urea is 5.0 mmol/L. Respiratory rate is 29 breaths per minute. Blood pressure is 120/80 mmHg. The patient is 65 years of age or older. | H7: =A7&"|"&B7&"|"&C7 -> gpt|no_guideline|15
A8: gpt | B8: no_guideline | C8: 16 | D8: Group2 | E8: Group2 | F8: =TRUE() -> TRUE | G8: The patient has an Abbreviated Mental Test Score (AMTS) of 10 out of 10. Blood urea is 5.0 mmol/L. Respiratory rate is 30 breaths per minute. Blood pressure is 120/80 mmHg. The patient is 65 years of age or older. | H8: =A8&"|"&B8&"|"&C8 -> gpt|no_guideline|16
A9: gpt | B9: no_guideline | C9: 17 | D9: Group1 | E9: Group1 | F9: =TRUE() -> TRUE | G9: The patient has an Abbreviated Mental Test Score (AMTS) of 10 out of 10. Blood urea is 5.0 mmol/L. Respiratory rate is 16 breaths per minute. Blood pressure is 120/61 mmHg. The patient is 65 years of age or older. | H9: =A9&"|"&B9&"|"&C9 -> gpt|no_guideline|17
A10: gpt | B10: no_guideline | C10: 18 | D10: Group2 | E10: Group1 | F10: =FALSE() -> FALSE | G10: The patient has an Abbreviated Mental Test Score (AMTS) of 10 out of 10. Blood urea is 5.0 mmol/L. Respiratory rate is 16 breaths per minute. Blood pressure is 120/60 mmHg. The patient is 65 years of age or older. | H10: =A10&"|"&B10&"|"&C10 -> gpt|no_guideline|18
A11: gpt | B11: no_guideline | C11: 19 | D11: Group1 | E11: Group2 | F11: =FALSE() -> FALSE | G11: The patient has an Abbreviated Mental Test Score (AMTS) of 10 out of 10. Blood urea is 5.0 mmol/L. Respiratory rate is 16 breaths per minute. Blood pressure is 90/80 mmHg. The patient is 65 years of age or older. | H11: =A11&"|"&B11&"|"&C11 -> gpt|no_guideline|19
A12: gpt | B12: no_guideline | C12: 20 | D12: Group2 | E12: Group2 | F12: =TRUE() -> TRUE | G12: The patient has an Abbreviated Mental Test Score (AMTS) of 10 out of 10. Blood urea is 5.0 mmol/L. Respiratory rate is 16 breaths per minute. Blood pressure is 89/80 mmHg. The patient is 65 years of age or older. | H12: =A12&"|"&B12&"|"&C12 -> gpt|no_guideline|20
A13: gpt | B13: no_guideline | C13: 21 | D13: Group2 | E13: Group2 | F13: =TRUE() -> TRUE | G13: The patient has an Abbreviated Mental Test Score (AMTS) of 10 out of 10. Blood urea is 5.0 mmol/L. Respiratory rate is 16 breaths per minute. Blood pressure is 85/55 mmHg. The patient is 65 years of age or older. | H13: =A13&"|"&B13&"|"&C13 -> gpt|no_guideline|21
A14: gpt | B14: no_guideline | C14: 22 | D14: Group1 | E14: Group1 | F14: =TRUE() -> TRUE | G14: The patient has an Abbreviated Mental Test Score (AMTS) of 8 out of 10. Blood urea is 5.0 mmol/L. Respiratory rate is 16 breaths per minute. Blood pressure is 120/80 mmHg. The patient is younger than 65 years of age. | H14: =A14&"|"&B14&"|"&C14 -> gpt|no_guideline|22
A15: gpt | B15: no_guideline | C15: 31 | D15: Group2 | E15: Group1 | F15: =FALSE() -> FALSE | G15: The patient has an Abbreviated Mental Test Score (AMTS) of 8 out of 10. Blood urea is 8.0 mmol/L. Respiratory rate is 16 breaths per minute. Blood pressure is 120/80 mmHg. The patient is younger than 65 years of age. | H15: =A15&"|"&B15&"|"&C15 -> gpt|no_guideline|31
A16: gpt | B16: no_guideline | C16: 32 | D16: Group3 | E16: Group2 | F16: =FALSE() -> FALSE | G16: The patient has an Abbreviated Mental Test Score (AMTS) of 8 out of 10. Blood urea is 8.0 mmol/L. Respiratory rate is 32 breaths per minute. Blood pressure is 120/80 mmHg. The patient is younger than 65 years of age. | H16: =A16&"|"&B16&"|"&C16 -> gpt|no_guideline|32
A17: gpt | B17: no_guideline | C17: 41 | D17: Group3 | E17: Group3 | F17: =TRUE() -> TRUE | G17: The patient has an Abbreviated Mental Test Score (AMTS) of 5 out of 10. Blood urea is 10.0 mmol/L. Respiratory rate is 35 breaths per minute. Blood pressure is 85/70 mmHg. The patient is younger than 65 years of age. | H17: =A17&"|"&B17&"|"&C17 -> gpt|no_guideline|41
A18: gpt | B18: no_guideline | C18: 42 | D18: Group3 | E18: Group3 | F18: =TRUE() -> TRUE | G18: The patient has an Abbreviated Mental Test Score (AMTS) of 3 out of 10. Blood urea is 12.0 mmol/L. Respiratory rate is 40 breaths per minute. Blood pressure is 80/50 mmHg. The patient is 65 years of age or older. | H18: =A18&"|"&B18&"|"&C18 -> gpt|no_guideline|42
A19: gpt | B19: no_guideline | C19: 51 | D19: Group2 | E19: Group2 | F19: =TRUE() -> TRUE | G19: The patient has an Abbreviated Mental Test Score (AMTS) of 6 out of 10. Blood urea is 5.0 mmol/L. Respiratory rate is 18 breaths per minute. Blood pressure is 130/75 mmHg. The patient is 65 years of age or older. | H19: =A19&"|"&B19&"|"&C19 -> gpt|no_guideline|51
A20: gpt | B20: no_guideline | C20: 52 | D20: Group2 | E20: Group3 | F20: =FALSE() -> FALSE | G20: The patient has an Abbreviated Mental Test Score (AMTS) of 10 out of 10. Blood urea is 4.0 mmol/L. Respiratory rate is 34 breaths per minute. Blood pressure is 82/55 mmHg. The patient is younger than 65 years of age. | H20: =A20&"|"&B20&"|"&C20 -> gpt|no_guideline|52
A21: gpt | B21: no_guideline | C21: 61 | D21: Group1 | E21: Group1 | F21: =TRUE() -> TRUE | G21: The patient has an Abbreviated Mental Test Score (AMTS) of 10 out of 10. Blood urea is 5.0 mmol/L. Respiratory rate is 16 breaths per minute. Blood pressure is 120/61 mmHg. The patient is 65 years of age or older. | H21: =A21&"|"&B21&"|"&C21 -> gpt|no_guideline|61
A22: gpt | B22: no_guideline | C22: 62 | D22: Group2 | E22: Group2 | F22: =TRUE() -> TRUE | G22: The patient has an Abbreviated Mental Test Score (AMTS) of 10 out of 10. Blood urea is 5.0 mmol/L. Respiratory rate is 16 breaths per minute. Blood pressure is 120/60 mmHg. The patient is 65 years of age or older. | H22: =A22&"|"&B22&"|"&C22 -> gpt|no_guideline|62
A23: gpt | B23: no_guideline | C23: 63 | D23: Group2 | E23: Group1 | F23: =FALSE() -> FALSE | G23: The patient has an Abbreviated Mental Test Score (AMTS) of 10 out of 10. Blood urea is 5.0 mmol/L. Respiratory rate is 16 breaths per minute. Blood pressure is 120/59 mmHg. The patient is 65 years of age or older. | H23: =A23&"|"&B23&"|"&C23 -> gpt|no_guideline|63
A24: gpt | B24: no_guideline | C24: 64 | D24: Group1 | E24: Group2 | F24: =FALSE() -> FALSE | G24: The patient has an Abbreviated Mental Test Score (AMTS) of 10 out of 10. Blood urea is 5.0 mmol/L. Respiratory rate is 16 breaths per minute. Blood pressure is 90/80 mmHg. The patient is 65 years of age or older. | H24: =A24&"|"&B24&"|"&C24 -> gpt|no_guideline|64
A25: gpt | B25: no_guideline | C25: 65 | D25: Group2 | E25: Group2 | F25: =TRUE() -> TRUE | G25: The patient has an Abbreviated Mental Test Score (AMTS) of 10 out of 10. Blood urea is 5.0 mmol/L. Respiratory rate is 16 breaths per minute. Blood pressure is 89/80 mmHg. The patient is 65 years of age or older. | H25: =A25&"|"&B25&"|"&C25 -> gpt|no_guideline|65
A26: gpt | B26: no_guideline | C26: 66 | D26: Group1 | E26: Group2 | F26: =FALSE() -> FALSE | G26: The patient has an Abbreviated Mental Test Score (AMTS) of 10 out of 10. Blood urea is 5.0 mmol/L. Respiratory rate is 16 breaths per minute. Blood pressure is 91/80 mmHg. The patient is 65 years of age or older. | H26: =A26&"|"&B26&"|"&C26 -> gpt|no_guideline|66
A27: gpt | B27: no_guideline | C27: 67 | D27: Group2 | E27: Group2 | F27: =TRUE() -> TRUE | G27: The patient has an Abbreviated Mental Test Score (AMTS) of 10 out of 10. Blood urea is 5.0 mmol/L. Respiratory rate is 16 breaths per minute. Blood pressure is 90/60 mmHg. The patient is 65 years of age or older. | H27: =A27&"|"&B27&"|"&C27 -> gpt|no_guideline|67
A28: gpt | B28: no_guideline | C28: 68 | D28: Group1 | E28: Group2 | F28: =FALSE() -> FALSE | G28: The patient has an Abbreviated Mental Test Score (AMTS) of 10 out of 10. Blood urea is 5.0 mmol/L. Respiratory rate is 16 breaths per minute. Blood pressure is 90/61 mmHg. The patient is 65 years of age or older. | H28: =A28&"|"&B28&"|"&C28 -> gpt|no_guideline|68
A29: gpt | B29: with_guideline | C29: 1 | D29: Group1 | E29: Group1 | F29: =TRUE() -> TRUE | G29: The patient has an Abbreviated Mental Test Score (AMTS) of 10 out of 10. Blood urea is 5.0 mmol/L. Respiratory rate is 16 breaths per minute. Blood pressure is 120/80 mmHg. The patient is younger than 65 years of age. | H29: =A29&"|"&B29&"|"&C29 -> gpt|with_guideline|1
A30: gpt | B30: with_guideline | C30: 11 | D30: Group1 | E30: Group1 | F30: =TRUE() -> TRUE | G30: The patient has an Abbreviated Mental Test Score (AMTS) of 9 out of 10. Blood urea is 5.0 mmol/L. Respiratory rate is 16 breaths per minute. Blood pressure is 120/80 mmHg. The patient is 65 years of age or older. | H30: =A30&"|"&B30&"|"&C30 -> gpt|with_guideline|11
A31: gpt | B31: with_guideline | C31: 12 | D31: Group2 | E31: Group1 | F31: =FALSE() -> FALSE | G31: The patient has an Abbreviated Mental Test Score (AMTS) of 8 out of 10. Blood urea is 5.0 mmol/L. Respiratory rate is 16 breaths per minute. Blood pressure is 120/80 mmHg. The patient is 65 years of age or older. | H31: =A31&"|"&B31&"|"&C31 -> gpt|with_guideline|12
A32: gpt | B32: with_guideline | C32: 13 | D32: Group1 | E32: Group1 | F32: =TRUE() -> TRUE | G32: The patient has an Abbreviated Mental Test Score (AMTS) of 10 out of 10. Blood urea is 7.0 mmol/L. Respiratory rate is 16 breaths per minute. Blood pressure is 120/80 mmHg. The patient is 65 years of age or older. | H32: =A32&"|"&B32&"|"&C32 -> gpt|with_guideline|13
A33: gpt | B33: with_guideline | C33: 14 | D33: Group2 | E33: Group2 | F33: =TRUE() -> TRUE | G33: The patient has an Abbreviated Mental Test Score (AMTS) of 10 out of 10. Blood urea is 7.1 mmol/L. Respiratory rate is 16 breaths per minute. Blood pressure is 120/80 mmHg. The patient is 65 years of age or older. | H33: =A33&"|"&B33&"|"&C33 -> gpt|with_guideline|14
A34: gpt | B34: with_guideline | C34: 15 | D34: Group1 | E34: Group1 | F34: =TRUE() -> TRUE | G34: The patient has an Abbreviated Mental Test Score (AMTS) of 10 out of 10. Blood urea is 5.0 mmol/L. Respiratory rate is 29 breaths per minute. Blood pressure is 120/80 mmHg. The patient is 65 years of age or older. | H34: =A34&"|"&B34&"|"&C34 -> gpt|with_guideline|15
A35: gpt | B35: with_guideline | C35: 16 | D35: Group2 | E35: Group2 | F35: =TRUE() -> TRUE | G35: The patient has an Abbreviated Mental Test Score (AMTS) of 10 out of 10. Blood urea is 5.0 mmol/L. Respiratory rate is 30 breaths per minute. Blood pressure is 120/80 mmHg. The patient is 65 years of age or older. | H35: =A35&"|"&B35&"|"&C35 -> gpt|with_guideline|16
A36: gpt | B36: with_guideline | C36: 17 | D36: Group1 | E36: Group1 | F36: =TRUE() -> TRUE | G36: The patient has an Abbreviated Mental Test Score (AMTS) of 10 out of 10. Blood urea is 5.0 mmol/L. Respiratory rate is 16 breaths per minute. Blood pressure is 120/61 mmHg. The patient is 65 years of age or older. | H36: =A36&"|"&B36&"|"&C36 -> gpt|with_guideline|17
A37: gpt | B37: with_guideline | C37: 18 | D37: Group2 | E37: Group1 | F37: =FALSE() -> FALSE | G37: The patient has an Abbreviated Mental Test Score (AMTS) of 10 out of 10. Blood urea is 5.0 mmol/L. Respiratory rate is 16 breaths per minute. Blood pressure is 120/60 mmHg. The patient is 65 years of age or older. | H37: =A37&"|"&B37&"|"&C37 -> gpt|with_guideline|18
A38: gpt | B38: with_guideline | C38: 19 | D38: Group1 | E38: Group2 | F38: =FALSE() -> FALSE | G38: The patient has an Abbreviated Mental Test Score (AMTS) of 10 out of 10. Blood urea is 5.0 mmol/L. Respiratory rate is 16 breaths per minute. Blood pressure is 90/80 mmHg. The patient is 65 years of age or older. | H38: =A38&"|"&B38&"|"&C38 -> gpt|with_guideline|19
A39: gpt | B39: with_guideline | C39: 20 | D39: Group2 | E39: Group2 | F39: =TRUE() -> TRUE | G39: The patient has an Abbreviated Mental Test Score (AMTS) of 10 out of 10. Blood urea is 5.0 mmol/L. Respiratory rate is 16 breaths per minute. Blood pressure is 89/80 mmHg. The patient is 65 years of age or older. | H39: =A39&"|"&B39&"|"&C39 -> gpt|with_guideline|20
A40: gpt | B40: with_guideline | C40: 21 | D40: Group2 | E40: Group2 | F40: =TRUE() -> TRUE | G40: The patient has an Abbreviated Mental Test Score (AMTS) of 10 out of 10. Blood urea is 5.0 mmol/L. Respiratory rate is 16 breaths per minute. Blood pressure is 85/55 mmHg. The patient is 65 years of age or older. | H40: =A40&"|"&B40&"|"&C40 -> gpt|with_guideline|21
...

Sheet dvt_eval
A1: Model | B1: Prompt | C1: Patient ID | D1: Expected | E1: Model Decision | F1: Correct | G1: Narrative | H1: Key
A2: gpt | B2: no_guideline | C2: 1 | D2: ExcludeDVT | E2: ExcludeDVT | F2: =TRUE() -> TRUE | G2: Active cancer is absent. Paralysis, paresis, or recent plaster immobilization of the lower extremities is absent. Recent bedridden status of more than 3 days or major surgery within the previous 12 weeks is absent. Localized tenderness along the deep venous system is absent. Swelling of the entire leg is absent. Calf swelling more than 3 cm larger than the asymptomatic side is absent. Pitting edema confined to the symptomatic leg is absent. Collateral superficial (nonvaricose) veins are absent. A previously documented DVT is absent. An alternative diagnosis at least as likely as DVT is absent. The D-dimer test result is Negative. The compression ultrasound result is Negative. | H2: =A2&"|"&B2&"|"&C2 -> gpt|no_guideline|1
A3: gpt | B3: no_guideline | C3: 2 | D3: ExcludeDVT | E3: TreatAnticoagulation | F3: =FALSE() -> FALSE | G3: Active cancer is absent. Paralysis, paresis, or recent plaster immobilization of the lower extremities is absent. Recent bedridden status of more than 3 days or major surgery within the previous 12 weeks is absent. Localized tenderness along the deep venous system is absent. Swelling of the entire leg is absent. Calf swelling more than 3 cm larger than the asymptomatic side is absent. Pitting edema confined to the symptomatic leg is absent. Collateral superficial (nonvaricose) veins are absent. A previously documented DVT is absent. An alternative diagnosis at least as likely as DVT is absent. The D-dimer test result is Negative. The compression ultrasound result is Positive. | H3: =A3&"|"&B3&"|"&C3 -> gpt|no_guideline|2
A4: gpt | B4: no_guideline | C4: 3 | D4: ExcludeDVT | E4: ExcludeDVT | F4: =TRUE() -> TRUE | G4: Active cancer is absent. Paralysis, paresis, or recent plaster immobilization of the lower extremities is absent. Recent bedridden status of more than 3 days or major surgery within the previous 12 weeks is absent. Localized tenderness along the deep venous system is absent. Swelling of the entire leg is absent. Calf swelling more than 3 cm larger than the asymptomatic side is absent. Pitting edema confined to the symptomatic leg is absent. Collateral superficial (nonvaricose) veins are absent. A previously documented DVT is absent. An alternative diagnosis at least as likely as DVT is absent. The D-dimer test result is Positive. The compression ultrasound result is Negative. | H4: =A4&"|"&B4&"|"&C4 -> gpt|no_guideline|3
A5: gpt | B5: no_guideline | C5: 4 | D5: TreatAnticoagulation | E5: TreatAnticoagulation | F5: =TRUE() -> TRUE | G5: Active cancer is absent. Paralysis, paresis, or recent plaster immobilization of the lower extremities is absent. Recent bedridden status of more than 3 days or major surgery within the previous 12 weeks is absent. Localized tenderness along the deep venous system is absent. Swelling of the entire leg is absent. Calf swelling more than 3 cm larger than the asymptomatic side is absent. Pitting edema confined to the symptomatic leg is absent. Collateral superficial (nonvaricose) veins are absent. A previously documented DVT is absent. An alternative diagnosis at least as likely as DVT is absent. The D-dimer test result is Positive. The compression ultrasound result is Positive. | H5: =A5&"|"&B5&"|"&C5 -> gpt|no_guideline|4
A6: gpt | B6: no_guideline | C6: 11 | D6: ExcludeDVT | E6: ExcludeDVT | F6: =TRUE() -> TRUE | G6: Active cancer is present. Paralysis, paresis, or recent plaster immobilization of the lower extremities is present. Recent bedridden status of more than 3 days or major surgery within the previous 12 weeks is absent. Localized tenderness along the deep venous system is absent. Swelling of the entire leg is absent. Calf swelling more than 3 cm larger than the asymptomatic side is absent. Pitting edema confined to the symptomatic leg is absent. Collateral superficial (nonvaricose) veins are absent. A previously documented DVT is absent. An alternative diagnosis at least as likely as DVT is absent. The D-dimer test result is Negative. The compression ultrasound result is Negative. | H6: =A6&"|"&B6&"|"&C6 -> gpt|no_guideline|11
A7: gpt | B7: no_guideline | C7: 12 | D7: TreatAnticoagulation | E7: TreatAnticoagulation | F7: =TRUE() -> TRUE | G7: Active cancer is present. Paralysis, paresis, or recent plaster immobilization of the lower extremities is present. Recent bedridden status of more than 3 days or major surgery within the previous 12 weeks is absent. Localized tenderness along the deep venous system is absent. Swelling of the entire leg is absent. Calf swelling more than 3 cm larger than the asymptomatic side is absent. Pitting edema confined to the symptomatic leg is absent. Collateral superficial (nonvaricose) veins are absent. A previously documented DVT is absent. An alternative diagnosis at least as likely as DVT is absent. The D-dimer test result is Negative. The compression ultrasound result is Positive. | H7: =A7&"|"&B7&"|"&C7 -> gpt|no_guideline|12
A8: gpt | B8: no_guideline | C8: 13 | D8: TreatAnticoagulation | E8: TreatAnticoagulation | F8: =TRUE() -> TRUE | G8: Active cancer is present. Paralysis, paresis, or recent plaster immobilization of the lower extremities is present. Recent bedridden status of more than 3 days or major surgery within the previous 12 weeks is absent. Localized tenderness along the deep venous system is absent. Swelling of the entire leg is absent. Calf swelling more than 3 cm larger than the asymptomatic side is absent. Pitting edema confined to the symptomatic leg is absent. Collateral superficial (nonvaricose) veins are absent. A previously documented DVT is absent. An alternative diagnosis at least as likely as DVT is absent. The D-dimer test result is Positive. The compression ultrasound result is Positive. | H8: =A8&"|"&B8&"|"&C8 -> gpt|no_guideline|13
A9: gpt | B9: no_guideline | C9: 14 | D9: RepeatUltrasoundIn1Week | E9: RepeatUltrasoundIn1Week | F9: =TRUE() -> TRUE | G9: Active cancer is present. Paralysis, paresis, or recent plaster immobilization of the lower extremities is present. Recent bedridden status of more than 3 days or major surgery within the previous 12 weeks is absent. Localized tenderness along the deep venous system is absent. Swelling of the entire leg is absent. Calf swelling more than 3 cm larger than the asymptomatic side is absent. Pitting edema confined to the symptomatic leg is absent. Collateral superficial (nonvaricose) veins are absent. A previously documented DVT is absent. An alternative diagnosis at least as likely as DVT is absent. The D-dimer test result is Positive. The compression ultrasound result is Negative. | H9: =A9&"|"&B9&"|"&C9 -> gpt|no_guideline|14
A10: gpt | B10: no_guideline | C10: 21 | D10: ExcludeDVT | E10: RepeatUltrasoundIn1Week | F10: =FALSE() -> FALSE | G10: Active cancer is absent. Paralysis, paresis, or recent plaster immobilization of the lower extremities is absent. Recent bedridden status of more than 3 days or major surgery within the previous 12 weeks is absent. Localized tenderness along the deep venous system is absent. Swelling of the entire leg is absent. Calf swelling more than 3 cm larger than the asymptomatic side is absent. Pitting edema confined to the symptomatic leg is absent. Collateral superficial (nonvaricose) veins are absent. A previously documented DVT is present. An alternative diagnosis at least as likely as DVT is absent. The D-dimer test result is Positive. The compression ultrasound result is Negative. | H10: =A10&"|"&B10&"|"&C10 -> gpt|no_guideline|21
A11: gpt | B11: no_guideline | C11: 22 | D11: RepeatUltrasoundIn1Week | E11: RepeatUltrasoundIn1Week | F11: =TRUE() -> TRUE | G11: Active cancer is present. Paralysis, paresis, or recent plaster immobilization of the lower extremities is absent. Recent bedridden status of more than 3 days or major surgery within the previous 12 weeks is absent. Localized tenderness along the deep venous system is absent. Swelling of the entire leg is absent. Calf swelling more than 3 cm larger than the asymptomatic side is absent. Pitting edema confined to the symptomatic leg is absent. Collateral superficial (nonvaricose) veins are absent. A previously documented DVT is present. An alternative diagnosis at least as likely as DVT is absent. The D-dimer test result is Positive. The compression ultrasound result is Negative. | H11: =A11&"|"&B11&"|"&C11 -> gpt|no_guideline|22
A12: gpt | B12: no_guideline | C12: 23 | D12: RepeatUltrasoundIn1Week | E12: RepeatUltrasoundIn1Week | F12: =TRUE() -> TRUE | G12: Active cancer is absent. Paralysis, paresis, or recent plaster immobilization of the lower extremities is present. Recent bedridden status of more than 3 days or major surgery within the previous 12 weeks is absent. Localized tenderness along the deep venous system is absent. Swelling of the entire leg is absent. Calf swelling more than 3 cm larger than the asymptomatic side is absent. Pitting edema confined to the symptomatic leg is absent. Collateral superficial (nonvaricose) veins are absent. A previously documented DVT is present. An alternative diagnosis at least as likely as DVT is absent. The D-dimer test result is Positive. The compression ultrasound result is Negative. | H12: =A12&"|"&B12&"|"&C12 -> gpt|no_guideline|23
A13: gpt | B13: no_guideline | C13: 24 | D13: RepeatUltrasoundIn1Week | E13: RepeatUltrasoundIn1Week | F13: =TRUE() -> TRUE | G13: Active cancer is absent. Paralysis, paresis, or recent plaster immobilization of the lower extremities is absent. Recent bedridden status of more than 3 days or major surgery within the previous 12 weeks is present. Localized tenderness along the deep venous system is absent. Swelling of the entire leg is absent. Calf swelling more than 3 cm larger than the asymptomatic side is absent. Pitting edema confined to the symptomatic leg is absent. Collateral superficial (nonvaricose) veins are absent. A previously documented DVT is present. An alternative diagnosis at least as likely as DVT is absent. The D-dimer test result is Positive. The compression ultrasound result is Negative. | H13: =A13&"|"&B13&"|"&C13 -> gpt|no_guideline|24
A14: gpt | B14: no_guideline | C14: 25 | D14: RepeatUltrasoundIn1Week | E14: RepeatUltrasoundIn1Week | F14: =TRUE() -> TRUE | G14: Active cancer is absent. Paralysis, paresis, or recent plaster immobilization of the lower extremities is absent. Recent bedridden status of more than 3 days or major surgery within the previous 12 weeks is absent. Localized tenderness along the deep venous system is present. Swelling of the entire leg is absent. Calf swelling more than 3 cm larger than the asymptomatic side is absent. Pitting edema confined to the symptomatic leg is absent. Collateral superficial (nonvaricose) veins are absent. A previously documented DVT is present. An alternative diagnosis at least as likely as DVT is absent. The D-dimer test result is Positive. The compression ultrasound result is Negative. | H14: =A14&"|"&B14&"|"&C14 -> gpt|no_guideline|25
A15: gpt | B15: no_guideline | C15: 26 | D15: RepeatUltrasoundIn1Week | E15: RepeatUltrasoundIn1Week | F15: =TRUE() -> TRUE | G15: Active cancer is absent. Paralysis, paresis, or recent plaster immobilization of the lower extremities is absent. Recent bedridden status of more than 3 days or major surgery within the previous 12 weeks is absent. Localized tenderness along the deep venous system is absent. Swelling of the entire leg is present. Calf swelling more than 3 cm larger than the asymptomatic side is absent. Pitting edema confined to the symptomatic leg is absent. Collateral superficial (nonvaricose) veins are absent. A previously documented DVT is present. An alternative diagnosis at least as likely as DVT is absent. The D-dimer test result is Positive. The compression ultrasound result is Negative. | H15: =A15&"|"&B15&"|"&C15 -> gpt|no_guideline|26
A16: gpt | B16: no_guideline | C16: 27 | D16: RepeatUltrasoundIn1Week | E16: RepeatUltrasoundIn1Week | F16: =TRUE() -> TRUE | G16: Active cancer is absent. Paralysis, paresis, or recent plaster immobilization of the lower extremities is absent. Recent bedridden status of more than 3 days or major surgery within the previous 12 weeks is absent. Localized tenderness along the deep venous system is absent. Swelling of the entire leg is absent. Calf swelling more than 3 cm larger than the asymptomatic side is present. Pitting edema confined to the symptomatic leg is absent. Collateral superficial (nonvaricose) veins are absent. A previously documented DVT is present. An alternative diagnosis at least as likely as DVT is absent. The D-dimer test result is Positive. The compression ultrasound result is Negative. | H16: =A16&"|"&B16&"|"&C16 -> gpt|no_guideline|27
A17: gpt | B17: no_guideline | C17: 28 | D17: RepeatUltrasoundIn1Week | E17: RepeatUltrasoundIn1Week | F17: =TRUE() -> TRUE | G17: Active cancer is absent. Paralysis, paresis, or recent plaster immobilization of the lower extremities is absent. Recent bedridden status of more than 3 days or major surgery within the previous 12 weeks is absent. Localized tenderness along the deep venous system is absent. Swelling of the entire leg is absent. Calf swelling more than 3 cm larger than the asymptomatic side is absent. Pitting edema confined to the symptomatic leg is present. Collateral superficial (nonvaricose) veins are absent. A previously documented DVT is present. An alternative diagnosis at least as likely as DVT is absent. The D-dimer test result is Positive. The compression ultrasound result is Negative. | H17: =A17&"|"&B17&"|"&C17 -> gpt|no_guideline|28
A18: gpt | B18: no_guideline | C18: 29 | D18: RepeatUltrasoundIn1Week | E18: RepeatUltrasoundIn1Week | F18: =TRUE() -> TRUE | G18: Active cancer is absent. Paralysis, paresis, or recent plaster immobilization of the lower extremities is absent. Recent bedridden status of more than 3 days or major surgery within the previous 12 weeks is absent. Localized tenderness along the deep venous system is absent. Swelling of the entire leg is absent. Calf swelling more than 3 cm larger than the asymptomatic side is absent. Pitting edema confined to the symptomatic leg is absent. Collateral superficial (nonvaricose) veins are present. A previously documented DVT is present. An alternative diagnosis at least as likely as DVT is absent. The D-dimer test result is Positive. The compression ultrasound result is Negative. | H18: =A18&"|"&B18&"|"&C18 -> gpt|no_guideline|29
